Workbook

Sheet Resumen
A1: Medidas por modelo (mm a la altura de referencia; proporciones, conteos y % sin unidad)
A2: ="Escala: "&Notas!B3&" mm de altura por modelo · celdas vacías = esa medida no se pudo sacar en ese modelo" -> Escala: 95 mm de altura por modelo · celdas vacías = esa medida no se pudo sacar en ese modelo
C3: T-pose | G3: Pose relajada | L3: Parciales
A4: Parte | B4: Medida | C4: 2a3facb9 | D4: 2f639739 | E4: 5dc9e0d5 | F4: a501b501 | G4: 2b65e967 | H4: 5ed925a3 | I4: 70ef0058 | J4: 80c13944 | K4: fba550bc | L4: 38448021 | M4: 6e95d62d
A5: general | B5: altura total | C5: =SUMIFS(Detalle!$I$2:$I$1370,Detalle!$A$2:$A$1370,"2a3facb9-object_2",Detalle!$B$2:$B$1370,$A5,Detalle!$C$2:$C$1370,$B5) -> 95 | D5: =SUMIFS(Detalle!$I$2:$I$1370,Detalle!$A$2:$A$1370,"2f639739-object_1",Detalle!$B$2:$B$1370,$A5,Detalle!$C$2:$C$1370,$B5) -> 95 | E5: =SUMIFS(Detalle!$I$2:$I$1370,Detalle!$A$2:$A$1370,"5dc9e0d5-object_0",Detalle!$B$2:$B$1370,$A5,Detalle!$C$2:$C$1370,$B5) -> 95 | F5: =SUMIFS(Detalle!$I$2:$I$1370,Detalle!$A$2:$A$1370,"a501b501-object_3",Detalle!$B$2:$B$1370,$A5,Detalle!$C$2:$C$1370,$B5) -> 95 | G5: =SUMIFS(Detalle!$I$2:$I$1370,Detalle!$A$2:$A$1370,"2b65e967-object_0-1",Detalle!$B$2:$B$1370,$A5,Detalle!$C$2:$C$1370,$B5) -> 95 | H5: =SUMIFS(Detalle!$I$2:$I$1370,Detalle!$A$2:$A$1370,"5ed925a3-object_2",Detalle!$B$2:$B$1370,$A5,Detalle!$C$2:$C$1370,$B5) -> 95 | I5: =SUMIFS(Detalle!$I$2:$I$1370,Detalle!$A$2:$A$1370,"70ef0058-object_0",Detalle!$B$2:$B$1370,$A5,Detalle!$C$2:$C$1370,$B5) -> 95 | J5: =SUMIFS(Detalle!$I$2:$I$1370,Detalle!$A$2:$A$1370,"80c13944-object_3",Detalle!$B$2:$B$1370,$A5,Detalle!$C$2:$C$1370,$B5) -> 95 | K5: =SUMIFS(Detalle!$I$2:$I$1370,Detalle!$A$2:$A$1370,"fba550bc-object_1",Detalle!$B$2:$B$1370,$A5,Detalle!$C$2:$C$1370,$B5) -> 95 | L5: =SUMIFS(Detalle!$I$2:$I$1370,Detalle!$A$2:$A$1370,"38448021-object_5",Detalle!$B$2:$B$1370,$A5,Detalle!$C$2:$C$1370,$B5) -> 95 | M5: =SUMIFS(Detalle!$I$2:$I$1370,Detalle!$A$2:$A$1370,"6e95d62d-object_4",Detalle!$B$2:$B$1370,$A5,Detalle!$C$2:$C$1370,$B5) -> 95
A6: general | B6: ancho total (X) | C6: =SUMIFS(Detalle!$I$2:$I$1370,Detalle!$A$2:$A$1370,"2a3facb9-object_2",Detalle!$B$2:$B$1370,$A6,Detalle!$C$2:$C$1370,$B6) -> 98.88775 | D6: =SUMIFS(Detalle!$I$2:$I$1370,Detalle!$A$2:$A$1370,"2f639739-object_1",Detalle!$B$2:$B$1370,$A6,Detalle!$C$2:$C$1370,$B6) -> 79.049072 | E6: =SUMIFS(Detalle!$I$2:$I$1370,Detalle!$A$2:$A$1370,"5dc9e0d5-object_0",Detalle!$B$2:$B$1370,$A6,Detalle!$C$2:$C$1370,$B6) -> 101.39396 | F6: =SUMIFS(Detalle!$I$2:$I$1370,Detalle!$A$2:$A$1370,"a501b501-object_3",Detalle!$B$2:$B$1370,$A6,Detalle!$C$2:$C$1370,$B6) -> 63.353916 | G6: =SUMIFS(Detalle!$I$2:$I$1370,Detalle!$A$2:$A$1370,"2b65e967-object_0-1",Detalle!$B$2:$B$1370,$A6,Detalle!$C$2:$C$1370,$B6) -> 50.141878 | H6: =SUMIFS(Detalle!$I$2:$I$1370,Detalle!$A$2:$A$1370,"5ed925a3-object_2",Detalle!$B$2:$B$1370,$A6,Detalle!$C$2:$C$1370,$B6) -> 46.333313 | I6: =SUMIFS(Detalle!$I$2:$I$1370,Detalle!$A$2:$A$1370,"70ef0058-object_0",Detalle!$B$2:$B$1370,$A6,Detalle!$C$2:$C$1370,$B6) -> 58.069129 | J6: =SUMIFS(Detalle!$I$2:$I$1370,Detalle!$A$2:$A$1370,"80c13944-object_3",Detalle!$B$2:$B$1370,$A6,Detalle!$C$2:$C$1370,$B6) -> 49.225221 | K6: =SUMIFS(Detalle!$I$2:$I$1370,Detalle!$A$2:$A$1370,"fba550bc-object_1",Detalle!$B$2:$B$1370,$A6,Detalle!$C$2:$C$1370,$B6) -> 46.824586 | L6: =SUMIFS(Detalle!$I$2:$I$1370,Detalle!$A$2:$A$1370,"38448021-object_5",Detalle!$B$2:$B$1370,$A6,Detalle!$C$2:$C$1370,$B6) -> 91.584381 | M6: =SUMIFS(Detalle!$I$2:$I$1370,Detalle!$A$2:$A$1370,"6e95d62d-object_4",Detalle!$B$2:$B$1370,$A6,Detalle!$C$2:$C$1370,$B6) -> 127.6631
A7: general | B7: fondo total (Z) | C7: =SUMIFS(Detalle!$I$2:$I$1370,Detalle!$A$2:$A$1370,"2a3facb9-object_2",Detalle!$B$2:$B$1370,$A7,Detalle!$C$2:$C$1370,$B7) -> 36.680768 | D7: =SUMIFS(Detalle!$I$2:$I$1370,Detalle!$A$2:$A$1370,"2f639739-object_1",Detalle!$B$2:$B$1370,$A7,Detalle!$C$2:$C$1370,$B7) -> 41.953073 | E7: =SUMIFS(Detalle!$I$2:$I$1370,Detalle!$A$2:$A$1370,"5dc9e0d5-object_0",Detalle!$B$2:$B$1370,$A7,Detalle!$C$2:$C$1370,$B7) -> 36.65666 | F7: =SUMIFS(Detalle!$I$2:$I$1370,Detalle!$A$2:$A$1370,"a501b501-object_3",Detalle!$B$2:$B$1370,$A7,Detalle!$C$2:$C$1370,$B7) -> 31.120739 | G7: =SUMIFS(Detalle!$I$2:$I$1370,Detalle!$A$2:$A$1370,"2b65e967-object_0-1",Detalle!$B$2:$B$1370,$A7,Detalle!$C$2:$C$1370,$B7) -> 37.702342 | H7: =SUMIFS(Detalle!$I$2:$I$1370,Detalle!$A$2:$A$1370,"5ed925a3-object_2",Detalle!$B$2:$B$1370,$A7,Detalle!$C$2:$C$1370,$B7) -> 43.182595 | I7: =SUMIFS(Detalle!$I$2:$I$1370,Detalle!$A$2:$A$1370,"70ef0058-object_0",Detalle!$B$2:$B$1370,$A7,Detalle!$C$2:$C$1370,$B7) -> 40.303866 | J7: =SUMIFS(Detalle!$I$2:$I$1370,Detalle!$A$2:$A$1370,"80c13944-object_3",Detalle!$B$2:$B$1370,$A7,Detalle!$C$2:$C$1370,$B7) -> 38.882467 | K7: =SUMIFS(Detalle!$I$2:$I$1370,Detalle!$A$2:$A$1370,"fba550bc-object_1",Detalle!$B$2:$B$1370,$A7,Detalle!$C$2:$C$1370,$B7) -> 43.164707 | L7: =SUMIFS(Detalle!$I$2:$I$1370,Detalle!$A$2:$A$1370,"38448021-object_5",Detalle!$B$2:$B$1370,$A7,Detalle!$C$2:$C$1370,$B7) -> 73.306638 | M7: =SUMIFS(Detalle!$I$2:$I$1370,Detalle!$A$2:$A$1370,"6e95d62d-object_4",Detalle!$B$2:$B$1370,$A7,Detalle!$C$2:$C$1370,$B7) -> 135.97786
A8: general | B8: triángulos | C8: =SUMIFS(Detalle!$I$2:$I$1370,Detalle!$A$2:$A$1370,"2a3facb9-object_2",Detalle!$B$2:$B$1370,$A8,Detalle!$C$2:$C$1370,$B8) -> 7681 | D8: =SUMIFS(Detalle!$I$2:$I$1370,Detalle!$A$2:$A$1370,"2f639739-object_1",Detalle!$B$2:$B$1370,$A8,Detalle!$C$2:$C$1370,$B8) -> 8656 | E8: =SUMIFS(Detalle!$I$2:$I$1370,Detalle!$A$2:$A$1370,"5dc9e0d5-object_0",Detalle!$B$2:$B$1370,$A8,Detalle!$C$2:$C$1370,$B8) -> 8996 | F8: =SUMIFS(Detalle!$I$2:$I$1370,Detalle!$A$2:$A$1370,"a501b501-object_3",Detalle!$B$2:$B$1370,$A8,Detalle!$C$2:$C$1370,$B8) -> 5472 | G8: =SUMIFS(Detalle!$I$2:$I$1370,Detalle!$A$2:$A$1370,"2b65e967-object_0-1",Detalle!$B$2:$B$1370,$A8,Detalle!$C$2:$C$1370,$B8) -> 9733 | H8: =SUMIFS(Detalle!$I$2:$I$1370,Detalle!$A$2:$A$1370,"5ed925a3-object_2",Detalle!$B$2:$B$1370,$A8,Detalle!$C$2:$C$1370,$B8) -> 7548 | I8: =SUMIFS(Detalle!$I$2:$I$1370,Detalle!$A$2:$A$1370,"70ef0058-object_0",Detalle!$B$2:$B$1370,$A8,Detalle!$C$2:$C$1370,$B8) -> 9014 | J8: =SUMIFS(Detalle!$I$2:$I$1370,Detalle!$A$2:$A$1370,"80c13944-object_3",Detalle!$B$2:$B$1370,$A8,Detalle!$C$2:$C$1370,$B8) -> 9848 | K8: =SUMIFS(Detalle!$I$2:$I$1370,Detalle!$A$2:$A$1370,"fba550bc-object_1",Detalle!$B$2:$B$1370,$A8,Detalle!$C$2:$C$1370,$B8) -> 9289 | L8: =SUMIFS(Detalle!$I$2:$I$1370,Detalle!$A$2:$A$1370,"38448021-object_5",Detalle!$B$2:$B$1370,$A8,Detalle!$C$2:$C$1370,$B8) -> 14198 | M8: =SUMIFS(Detalle!$I$2:$I$1370,Detalle!$A$2:$A$1370,"6e95d62d-object_4",Detalle!$B$2:$B$1370,$A8,Detalle!$C$2:$C$1370,$B8) -> 11738
A9: general | B9: vértices (soldados) | C9: =SUMIFS(Detalle!$I$2:$I$1370,Detalle!$A$2:$A$1370,"2a3facb9-object_2",Detalle!$B$2:$B$1370,$A9,Detalle!$C$2:$C$1370,$B9) -> 3841 | D9: =SUMIFS(Detalle!$I$2:$I$1370,Detalle!$A$2:$A$1370,"2f639739-object_1",Detalle!$B$2:$B$1370,$A9,Detalle!$C$2:$C$1370,$B9) -> 4328 | E9: =SUMIFS(Detalle!$I$2:$I$1370,Detalle!$A$2:$A$1370,"5dc9e0d5-object_0",Detalle!$B$2:$B$1370,$A9,Detalle!$C$2:$C$1370,$B9) -> 4493 | F9: =SUMIFS(Detalle!$I$2:$I$1370,Detalle!$A$2:$A$1370,"a501b501-object_3",Detalle!$B$2:$B$1370,$A9,Detalle!$C$2:$C$1370,$B9) -> 2736 | G9: =SUMIFS(Detalle!$I$2:$I$1370,Detalle!$A$2:$A$1370,"2b65e967-object_0-1",Detalle!$B$2:$B$1370,$A9,Detalle!$C$2:$C$1370,$B9) -> 4861 | H9: =SUMIFS(Detalle!$I$2:$I$1370,Detalle!$A$2:$A$1370,"5ed925a3-object_2",Detalle!$B$2:$B$1370,$A9,Detalle!$C$2:$C$1370,$B9) -> 3773 | I9: =SUMIFS(Detalle!$I$2:$I$1370,Detalle!$A$2:$A$1370,"70ef0058-object_0",Detalle!$B$2:$B$1370,$A9,Detalle!$C$2:$C$1370,$B9) -> 4505 | J9: =SUMIFS(Detalle!$I$2:$I$1370,Detalle!$A$2:$A$1370,"80c13944-object_3",Detalle!$B$2:$B$1370,$A9,Detalle!$C$2:$C$1370,$B9) -> 4922 | K9: =SUMIFS(Detalle!$I$2:$I$1370,Detalle!$A$2:$A$1370,"fba550bc-object_1",Detalle!$B$2:$B$1370,$A9,Detalle!$C$2:$C$1370,$B9) -> 4641 | L9: =SUMIFS(Detalle!$I$2:$I$1370,Detalle!$A$2:$A$1370,"38448021-object_5",Detalle!$B$2:$B$1370,$A9,Detalle!$C$2:$C$1370,$B9) -> 7101 | M9: =SUMIFS(Detalle!$I$2:$I$1370,Detalle!$A$2:$A$1370,"6e95d62d-object_4",Detalle!$B$2:$B$1370,$A9,Detalle!$C$2:$C$1370,$B9) -> 5871
A10: general | B10: área de superficie (u²) | C10: =SUMIFS(Detalle!$I$2:$I$1370,Detalle!$A$2:$A$1370,"2a3facb9-object_2",Detalle!$B$2:$B$1370,$A10,Detalle!$C$2:$C$1370,$B10) -> 1.52798 | D10: =SUMIFS(Detalle!$I$2:$I$1370,Detalle!$A$2:$A$1370,"2f639739-object_1",Detalle!$B$2:$B$1370,$A10,Detalle!$C$2:$C$1370,$B10) -> 1.60298 | E10: =SUMIFS(Detalle!$I$2:$I$1370,Detalle!$A$2:$A$1370,"5dc9e0d5-object_0",Detalle!$B$2:$B$1370,$A10,Detalle!$C$2:$C$1370,$B10) -> 1.52378 | F10: =SUMIFS(Detalle!$I$2:$I$1370,Detalle!$A$2:$A$1370,"a501b501-object_3",Detalle!$B$2:$B$1370,$A10,Detalle!$C$2:$C$1370,$B10) -> 0.95616 | G10: =SUMIFS(Detalle!$I$2:$I$1370,Detalle!$A$2:$A$1370,"2b65e967-object_0-1",Detalle!$B$2:$B$1370,$A10,Detalle!$C$2:$C$1370,$B10) -> 1.68257 | H10: =SUMIFS(Detalle!$I$2:$I$1370,Detalle!$A$2:$A$1370,"5ed925a3-object_2",Detalle!$B$2:$B$1370,$A10,Detalle!$C$2:$C$1370,$B10) -> 1.44833 | I10: =SUMIFS(Detalle!$I$2:$I$1370,Detalle!$A$2:$A$1370,"70ef0058-object_0",Detalle!$B$2:$B$1370,$A10,Detalle!$C$2:$C$1370,$B10) -> 1.69059 | J10: =SUMIFS(Detalle!$I$2:$I$1370,Detalle!$A$2:$A$1370,"80c13944-object_3",Detalle!$B$2:$B$1370,$A10,Detalle!$C$2:$C$1370,$B10) -> 1.66565 | K10: =SUMIFS(Detalle!$I$2:$I$1370,Detalle!$A$2:$A$1370,"fba550bc-object_1",Detalle!$B$2:$B$1370,$A10,Detalle!$C$2:$C$1370,$B10) -> 1.59836 | L10: =SUMIFS(Detalle!$I$2:$I$1370,Detalle!$A$2:$A$1370,"38448021-object_5",Detalle!$B$2:$B$1370,$A10,Detalle!$C$2:$C$1370,$B10) -> 2.9149 | M10: =SUMIFS(Detalle!$I$2:$I$1370,Detalle!$A$2:$A$1370,"6e95d62d-object_4",Detalle!$B$2:$B$1370,$A10,Detalle!$C$2:$C$1370,$B10) -> 3.05969
A11: general | B11: volumen aprox (u³) | C11: =SUMIFS(Detalle!$I$2:$I$1370,Detalle!$A$2:$A$1370,"2a3facb9-object_2",Detalle!$B$2:$B$1370,$A11,Detalle!$C$2:$C$1370,$B11) -> 0.05452 | D11: =SUMIFS(Detalle!$I$2:$I$1370,Detalle!$A$2:$A$1370,"2f639739-object_1",Detalle!$B$2:$B$1370,$A11,Detalle!$C$2:$C$1370,$B11) -> 0.06099 | E11: =SUMIFS(Detalle!$I$2:$I$1370,Detalle!$A$2:$A$1370,"5dc9e0d5-object_0",Detalle!$B$2:$B$1370,$A11,Detalle!$C$2:$C$1370,$B11) -> 0.05615 | F11: =SUMIFS(Detalle!$I$2:$I$1370,Detalle!$A$2:$A$1370,"a501b501-object_3",Detalle!$B$2:$B$1370,$A11,Detalle!$C$2:$C$1370,$B11) -> 0.02755 | G11: =SUMIFS(Detalle!$I$2:$I$1370,Detalle!$A$2:$A$1370,"2b65e967-object_0-1",Detalle!$B$2:$B$1370,$A11,Detalle!$C$2:$C$1370,$B11) -> 0.05312 | H11: =SUMIFS(Detalle!$I$2:$I$1370,Detalle!$A$2:$A$1370,"5ed925a3-object_2",Detalle!$B$2:$B$1370,$A11,Detalle!$C$2:$C$1370,$B11) -> 0.05484 | I11: =SUMIFS(Detalle!$I$2:$I$1370,Detalle!$A$2:$A$1370,"70ef0058-object_0",Detalle!$B$2:$B$1370,$A11,Detalle!$C$2:$C$1370,$B11) -> 0.06921 | J11: =SUMIFS(Detalle!$I$2:$I$1370,Detalle!$A$2:$A$1370,"80c13944-object_3",Detalle!$B$2:$B$1370,$A11,Detalle!$C$2:$C$1370,$B11) -> 0.05386 | K11: =SUMIFS(Detalle!$I$2:$I$1370,Detalle!$A$2:$A$1370,"fba550bc-object_1",Detalle!$B$2:$B$1370,$A11,Detalle!$C$2:$C$1370,$B11) -> 0.05682 | L11: =SUMIFS(Detalle!$I$2:$I$1370,Detalle!$A$2:$A$1370,"38448021-object_5",Detalle!$B$2:$B$1370,$A11,Detalle!$C$2:$C$1370,$B11) -> 0.20608 | M11: =SUMIFS(Detalle!$I$2:$I$1370,Detalle!$A$2:$A$1370,"6e95d62d-object_4",Detalle!$B$2:$B$1370,$A11,Detalle!$C$2:$C$1370,$B11) -> 0.25498
A12: color | B12: % superficie calido | C12: =SUMIFS(Detalle!$I$2:$I$1370,Detalle!$A$2:$A$1370,"2a3facb9-object_2",Detalle!$B$2:$B$1370,$A12,Detalle!$C$2:$C$1370,$B12) -> 50.94077 | D12: =SUMIFS(Detalle!$I$2:$I$1370,Detalle!$A$2:$A$1370,"2f639739-object_1",Detalle!$B$2:$B$1370,$A12,Detalle!$C$2:$C$1370,$B12) -> 57.74323 | E12: =SUMIFS(Detalle!$I$2:$I$1370,Detalle!$A$2:$A$1370,"5dc9e0d5-object_0",Detalle!$B$2:$B$1370,$A12,Detalle!$C$2:$C$1370,$B12) -> 54.33839 | F12: =SUMIFS(Detalle!$I$2:$I$1370,Detalle!$A$2:$A$1370,"a501b501-object_3",Detalle!$B$2:$B$1370,$A12,Detalle!$C$2:$C$1370,$B12) -> 58.90568 | G12: =SUMIFS(Detalle!$I$2:$I$1370,Detalle!$A$2:$A$1370,"2b65e967-object_0-1",Detalle!$B$2:$B$1370,$A12,Detalle!$C$2:$C$1370,$B12) -> 53.29167 | H12: =SUMIFS(Detalle!$I$2:$I$1370,Detalle!$A$2:$A$1370,"5ed925a3-object_2",Detalle!$B$2:$B$1370,$A12,Detalle!$C$2:$C$1370,$B12) -> 56.83707 | I12: =SUMIFS(Detalle!$I$2:$I$1370,Detalle!$A$2:$A$1370,"70ef0058-object_0",Detalle!$B$2:$B$1370,$A12,Detalle!$C$2:$C$1370,$B12) -> 59.15974 | J12: =SUMIFS(Detalle!$I$2:$I$1370,Detalle!$A$2:$A$1370,"80c13944-object_3",Detalle!$B$2:$B$1370,$A12,Detalle!$C$2:$C$1370,$B12) -> 54.69215 | K12: =SUMIFS(Detalle!$I$2:$I$1370,Detalle!$A$2:$A$1370,"fba550bc-object_1",Detalle!$B$2:$B$1370,$A12,Detalle!$C$2:$C$1370,$B12) -> 63.07858 | L12: =SUMIFS(Detalle!$I$2:$I$1370,Detalle!$A$2:$A$1370,"38448021-object_5",Detalle!$B$2:$B$1370,$A12,Detalle!$C$2:$C$1370,$B12) -> 83.42761 | M12: =SUMIFS(Detalle!$I$2:$I$1370,Detalle!$A$2:$A$1370,"6e95d62d-object_4",Detalle!$B$2:$B$1370,$A12,Detalle!$C$2:$C$1370,$B12) -> 91.39934
A13: color | B13: % superficie blanco | C13: =SUMIFS(Detalle!$I$2:$I$1370,Detalle!$A$2:$A$1370,"2a3facb9-object_2",Detalle!$B$2:$B$1370,$A13,Detalle!$C$2:$C$1370,$B13) -> 10.21058 | D13: =SUMIFS(Detalle!$I$2:$I$1370,Detalle!$A$2:$A$1370,"2f639739-object_1",Detalle!$B$2:$B$1370,$A13,Detalle!$C$2:$C$1370,$B13) -> 10.26021 | E13: =SUMIFS(Detalle!$I$2:$I$1370,Detalle!$A$2:$A$1370,"5dc9e0d5-object_0",Detalle!$B$2:$B$1370,$A13,Detalle!$C$2:$C$1370,$B13) -> 9.86556 | F13: =SUMIFS(Detalle!$I$2:$I$1370,Detalle!$A$2:$A$1370,"a501b501-object_3",Detalle!$B$2:$B$1370,$A13,Detalle!$C$2:$C$1370,$B13) -> 10.47675 | G13: =SUMIFS(Detalle!$I$2:$I$1370,Detalle!$A$2:$A$1370,"2b65e967-object_0-1",Detalle!$B$2:$B$1370,$A13,Detalle!$C$2:$C$1370,$B13) -> 7.16016 | H13: =SUMIFS(Detalle!$I$2:$I$1370,Detalle!$A$2:$A$1370,"5ed925a3-object_2",Detalle!$B$2:$B$1370,$A13,Detalle!$C$2:$C$1370,$B13) -> 7.76347 | I13: =SUMIFS(Detalle!$I$2:$I$1370,Detalle!$A$2:$A$1370,"70ef0058-object_0",Detalle!$B$2:$B$1370,$A13,Detalle!$C$2:$C$1370,$B13) -> 8.06698 | J13: =SUMIFS(Detalle!$I$2:$I$1370,Detalle!$A$2:$A$1370,"80c13944-object_3",Detalle!$B$2:$B$1370,$A13,Detalle!$C$2:$C$1370,$B13) -> 7.19519 | K13: =SUMIFS(Detalle!$I$2:$I$1370,Detalle!$A$2:$A$1370,"fba550bc-object_1",Detalle!$B$2:$B$1370,$A13,Detalle!$C$2:$C$1370,$B13) -> 7.8189 | L13: =SUMIFS(Detalle!$I$2:$I$1370,Detalle!$A$2:$A$1370,"38448021-object_5",Detalle!$B$2:$B$1370,$A13,Detalle!$C$2:$C$1370,$B13) -> 7.13803 | M13: =SUMIFS(Detalle!$I$2:$I$1370,Detalle!$A$2:$A$1370,"6e95d62d-object_4",Detalle!$B$2:$B$1370,$A13,Detalle!$C$2:$C$1370,$B13) -> 0
A14: color | B14: % superficie oscuro | C14: =SUMIFS(Detalle!$I$2:$I$1370,Detalle!$A$2:$A$1370,"2a3facb9-object_2",Detalle!$B$2:$B$1370,$A14,Detalle!$C$2:$C$1370,$B14) -> 29.81625 | D14: =SUMIFS(Detalle!$I$2:$I$1370,Detalle!$A$2:$A$1370,"2f639739-object_1",Detalle!$B$2:$B$1370,$A14,Detalle!$C$2:$C$1370,$B14) -> 25.94493 | E14: =SUMIFS(Detalle!$I$2:$I$1370,Detalle!$A$2:$A$1370,"5dc9e0d5-object_0",Detalle!$B$2:$B$1370,$A14,Detalle!$C$2:$C$1370,$B14) -> 31.75727 | F14: =SUMIFS(Detalle!$I$2:$I$1370,Detalle!$A$2:$A$1370,"a501b501-object_3",Detalle!$B$2:$B$1370,$A14,Detalle!$C$2:$C$1370,$B14) -> 17.55764 | G14: =SUMIFS(Detalle!$I$2:$I$1370,Detalle!$A$2:$A$1370,"2b65e967-object_0-1",Detalle!$B$2:$B$1370,$A14,Detalle!$C$2:$C$1370,$B14) -> 30.7105 | H14: =SUMIFS(Detalle!$I$2:$I$1370,Detalle!$A$2:$A$1370,"5ed925a3-object_2",Detalle!$B$2:$B$1370,$A14,Detalle!$C$2:$C$1370,$B14) -> 26.12954 | I14: =SUMIFS(Detalle!$I$2:$I$1370,Detalle!$A$2:$A$1370,"70ef0058-object_0",Detalle!$B$2:$B$1370,$A14,Detalle!$C$2:$C$1370,$B14) -> 25.89858 | J14: =SUMIFS(Detalle!$I$2:$I$1370,Detalle!$A$2:$A$1370,"80c13944-object_3",Detalle!$B$2:$B$1370,$A14,Detalle!$C$2:$C$1370,$B14) -> 28.93641 | K14: =SUMIFS(Detalle!$I$2:$I$1370,Detalle!$A$2:$A$1370,"fba550bc-object_1",Detalle!$B$2:$B$1370,$A14,Detalle!$C$2:$C$1370,$B14) -> 22.05436 | L14: =SUMIFS(Detalle!$I$2:$I$1370,Detalle!$A$2:$A$1370,"38448021-object_5",Detalle!$B$2:$B$1370,$A14,Detalle!$C$2:$C$1370,$B14) -> 9.15431 | M14: =SUMIFS(Detalle!$I$2:$I$1370,Detalle!$A$2:$A$1370,"6e95d62d-object_4",Detalle!$B$2:$B$1370,$A14,Detalle!$C$2:$C$1370,$B14) -> 8.60066
A15: color | B15: % superficie azul | C15: =SUMIFS(Detalle!$I$2:$I$1370,Detalle!$A$2:$A$1370,"2a3facb9-object_2",Detalle!$B$2:$B$1370,$A15,Detalle!$C$2:$C$1370,$B15) -> 9.0324 | D15: =SUMIFS(Detalle!$I$2:$I$1370,Detalle!$A$2:$A$1370,"2f639739-object_1",Detalle!$B$2:$B$1370,$A15,Detalle!$C$2:$C$1370,$B15) -> 6.05163 | E15: =SUMIFS(Detalle!$I$2:$I$1370,Detalle!$A$2:$A$1370,"5dc9e0d5-object_0",Detalle!$B$2:$B$1370,$A15,Detalle!$C$2:$C$1370,$B15) -> 4.03878 | F15: =SUMIFS(Detalle!$I$2:$I$1370,Detalle!$A$2:$A$1370,"a501b501-object_3",Detalle!$B$2:$B$1370,$A15,Detalle!$C$2:$C$1370,$B15) -> 13.05993 | G15: =SUMIFS(Detalle!$I$2:$I$1370,Detalle!$A$2:$A$1370,"2b65e967-object_0-1",Detalle!$B$2:$B$1370,$A15,Detalle!$C$2:$C$1370,$B15) -> 8.83768 | H15: =SUMIFS(Detalle!$I$2:$I$1370,Detalle!$A$2:$A$1370,"5ed925a3-object_2",Detalle!$B$2:$B$1370,$A15,Detalle!$C$2:$C$1370,$B15) -> 9.26993 | I15: =SUMIFS(Detalle!$I$2:$I$1370,Detalle!$A$2:$A$1370,"70ef0058-object_0",Detalle!$B$2:$B$1370,$A15,Detalle!$C$2:$C$1370,$B15) -> 6.8747 | J15: =SUMIFS(Detalle!$I$2:$I$1370,Detalle!$A$2:$A$1370,"80c13944-object_3",Detalle!$B$2:$B$1370,$A15,Detalle!$C$2:$C$1370,$B15) -> 9.17625 | K15: =SUMIFS(Detalle!$I$2:$I$1370,Detalle!$A$2:$A$1370,"fba550bc-object_1",Detalle!$B$2:$B$1370,$A15,Detalle!$C$2:$C$1370,$B15) -> 7.04816 | L15: =SUMIFS(Detalle!$I$2:$I$1370,Detalle!$A$2:$A$1370,"38448021-object_5",Detalle!$B$2:$B$1370,$A15,Detalle!$C$2:$C$1370,$B15) -> 0.28005 | M15: =SUMIFS(Detalle!$I$2:$I$1370,Detalle!$A$2:$A$1370,"6e95d62d-object_4",Detalle!$B$2:$B$1370,$A15,Detalle!$C$2:$C$1370,$B15) -> 0
A16: cabeza | B16: altura del cuello de camisa / base de cabeza | C16: =SUMIFS(Detalle!$I$2:$I$1370,Detalle!$A$2:$A$1370,"2a3facb9-object_2",Detalle!$B$2:$B$1370,$A16,Detalle!$C$2:$C$1370,$B16) -> 53.200477 | D16: =SUMIFS(Detalle!$I$2:$I$1370,Detalle!$A$2:$A$1370,"2f639739-object_1",Detalle!$B$2:$B$1370,$A16,Detalle!$C$2:$C$1370,$B16) -> 50.350352 | E16: =SUMIFS(Detalle!$I$2:$I$1370,Detalle!$A$2:$A$1370,"5dc9e0d5-object_0",Detalle!$B$2:$B$1370,$A16,Detalle!$C$2:$C$1370,$B16) -> 51.299838 | F16: =SUMIFS(Detalle!$I$2:$I$1370,Detalle!$A$2:$A$1370,"a501b501-object_3",Detalle!$B$2:$B$1370,$A16,Detalle!$C$2:$C$1370,$B16) -> 37.99962 | G16: =SUMIFS(Detalle!$I$2:$I$1370,Detalle!$A$2:$A$1370,"2b65e967-object_0-1",Detalle!$B$2:$B$1370,$A16,Detalle!$C$2:$C$1370,$B16) -> 53.200343 | H16: =SUMIFS(Detalle!$I$2:$I$1370,Detalle!$A$2:$A$1370,"5ed925a3-object_2",Detalle!$B$2:$B$1370,$A16,Detalle!$C$2:$C$1370,$B16) -> 52.250285 | I16: =SUMIFS(Detalle!$I$2:$I$1370,Detalle!$A$2:$A$1370,"70ef0058-object_0",Detalle!$B$2:$B$1370,$A16,Detalle!$C$2:$C$1370,$B16) -> 48.4502 | J16: =SUMIFS(Detalle!$I$2:$I$1370,Detalle!$A$2:$A$1370,"80c13944-object_3",Detalle!$B$2:$B$1370,$A16,Detalle!$C$2:$C$1370,$B16) -> 53.200419 | K16: =SUMIFS(Detalle!$I$2:$I$1370,Detalle!$A$2:$A$1370,"fba550bc-object_1",Detalle!$B$2:$B$1370,$A16,Detalle!$C$2:$C$1370,$B16) -> 53.20038 | L16: =SUMIFS(Detalle!$I$2:$I$1370,Detalle!$A$2:$A$1370,"38448021-object_5",Detalle!$B$2:$B$1370,$A16,Detalle!$C$2:$C$1370,$B16) -> 29.449744 | M16: =SUMIFS(Detalle!$I$2:$I$1370,Detalle!$A$2:$A$1370,"6e95d62d-object_4",Detalle!$B$2:$B$1370,$A16,Detalle!$C$2:$C$1370,$B16) -> 0
... A37: cabeza | B37: contorno a 50% de la cabeza | C37: =SUMIFS(Detalle!$I$2:$I$1370,Detalle!$A$2:$A$1370,"2a3facb9-object_2",Detalle!$B$2:$B$1370,$A37,Detalle!$C$2:$C$1370,$B37) -> 168.23237 | D37: =SUMIFS(Detalle!$I$2:$I$1370,Detalle!$A$2:$A$1370,"2f639739-object_1",Detalle!$B$2:$B$1370,$A37,Detalle!$C$2:$C$1370,$B37) -> 167.90656 | E37: =SUMIFS(Detalle!$I$2:$I$1370,Detalle!$A$2:$A$1370,"5dc9e0d5-object_0",Detalle!$B$2:$B$1370,$A37,Detalle!$C$2:$C$1370,$B37) -> 157.5187 | F37: =SUMIFS(Detalle!$I$2:$I$1370,Detalle!$A$2:$A$1370,"a501b501-object_3",Detalle!$B$2:$B$1370,$A37,Detalle!$C$2:$C$1370,$B37) -> 104.94735 | G37: =SUMIFS(Detalle!$I$2:$I$1370,Detalle!$A$2:$A$1370,"2b65e967-object_0-1",Detalle!$B$2:$B$1370,$A37,Detalle!$C$2:$C$1370,$B37) -> 176.25024 | H37: =SUMIFS(Detalle!$I$2:$I$1370,Detalle!$A$2:$A$1370,"5ed925a3-object_2",Detalle!$B$2:$B$1370,$A37,Detalle!$C$2:$C$1370,$B37) -> 154.20009 | I37: =SUMIFS(Detalle!$I$2:$I$1370,Detalle!$A$2:$A$1370,"70ef0058-object_0",Detalle!$B$2:$B$1370,$A37,Detalle!$C$2:$C$1370,$B37) -> 179.46462 | J37: =SUMIFS(Detalle!$I$2:$I$1370,Detalle!$A$2:$A$1370,"80c13944-object_3",Detalle!$B$2:$B$1370,$A37,Detalle!$C$2:$C$1370,$B37) -> 188.99811 | K37: =SUMIFS(Detalle!$I$2:$I$1370,Detalle!$A$2:$A$1370,"fba550bc-object_1",Detalle!$B$2:$B$1370,$A37,Detalle!$C$2:$C$1370,$B37) -> 186.6909 | L37: =SUMIFS(Detalle!$I$2:$I$1370,Detalle!$A$2:$A$1370,"38448021-object_5",Detalle!$B$2:$B$1370,$A37,Detalle!$C$2:$C$1370,$B37) -> 320.94854 | M37: =SUMIFS(Detalle!$I$2:$I$1370,Detalle!$A$2:$A$1370,"6e95d62d-object_4",Detalle!$B$2:$B$1370,$A37,Detalle!$C$2:$C$1370,$B37) -> 726.18446
A38: cabeza | B38: ancho a 75% de la cabeza | C38: =SUMIFS(Detalle!$I$2:$I$1370,Detalle!$A$2:$A$1370,"2a3facb9-object_2",Detalle!$B$2:$B$1370,$A38,Detalle!$C$2:$C$1370,$B38) -> 39.581926 | D38: =SUMIFS(Detalle!$I$2:$I$1370,Detalle!$A$2:$A$1370,"2f639739-object_1",Detalle!$B$2:$B$1370,$A38,Detalle!$C$2:$C$1370,$B38) -> 35.801034 | E38: =SUMIFS(Detalle!$I$2:$I$1370,Detalle!$A$2:$A$1370,"5dc9e0d5-object_0",Detalle!$B$2:$B$1370,$A38,Detalle!$C$2:$C$1370,$B38) -> 43.596641 | G38: =SUMIFS(Detalle!$I$2:$I$1370,Detalle!$A$2:$A$1370,"2b65e967-object_0-1",Detalle!$B$2:$B$1370,$A38,Detalle!$C$2:$C$1370,$B38) -> 42.479528 | H38: =SUMIFS(Detalle!$I$2:$I$1370,Detalle!$A$2:$A$1370,"5ed925a3-object_2",Detalle!$B$2:$B$1370,$A38,Detalle!$C$2:$C$1370,$B38) -> 35.487589 | I38: =SUMIFS(Detalle!$I$2:$I$1370,Detalle!$A$2:$A$1370,"70ef0058-object_0",Detalle!$B$2:$B$1370,$A38,Detalle!$C$2:$C$1370,$B38) -> 48.276226 | J38: =SUMIFS(Detalle!$I$2:$I$1370,Detalle!$A$2:$A$1370,"80c13944-object_3",Detalle!$B$2:$B$1370,$A38,Detalle!$C$2:$C$1370,$B38) -> 40.598641 | K38: =SUMIFS(Detalle!$I$2:$I$1370,Detalle!$A$2:$A$1370,"fba550bc-object_1",Detalle!$B$2:$B$1370,$A38,Detalle!$C$2:$C$1370,$B38) -> 33.934207 | L38: =SUMIFS(Detalle!$I$2:$I$1370,Detalle!$A$2:$A$1370,"38448021-object_5",Detalle!$B$2:$B$1370,$A38,Detalle!$C$2:$C$1370,$B38) -> 78.105222 | M38: =SUMIFS(Detalle!$I$2:$I$1370,Detalle!$A$2:$A$1370,"6e95d62d-object_4",Detalle!$B$2:$B$1370,$A38,Detalle!$C$2:$C$1370,$B38) -> 118.1401
A39: cabeza | B39: fondo a 75% de la cabeza | C39: =SUMIFS(Detalle!$I$2:$I$1370,Detalle!$A$2:$A$1370,"2a3facb9-object_2",Detalle!$B$2:$B$1370,$A39,Detalle!$C$2:$C$1370,$B39) -> 28.748287 | D39: =SUMIFS(Detalle!$I$2:$I$1370,Detalle!$A$2:$A$1370,"2f639739-object_1",Detalle!$B$2:$B$1370,$A39,Detalle!$C$2:$C$1370,$B39) -> 39.599282 | E39: =SUMIFS(Detalle!$I$2:$I$1370,Detalle!$A$2:$A$1370,"5dc9e0d5-object_0",Detalle!$B$2:$B$1370,$A39,Detalle!$C$2:$C$1370,$B39) -> 33.565232 | G39: =SUMIFS(Detalle!$I$2:$I$1370,Detalle!$A$2:$A$1370,"2b65e967-object_0-1",Detalle!$B$2:$B$1370,$A39,Detalle!$C$2:$C$1370,$B39) -> 30.896972 | H39: =SUMIFS(Detalle!$I$2:$I$1370,Detalle!$A$2:$A$1370,"5ed925a3-object_2",Detalle!$B$2:$B$1370,$A39,Detalle!$C$2:$C$1370,$B39) -> 30.843626 | I39: =SUMIFS(Detalle!$I$2:$I$1370,Detalle!$A$2:$A$1370,"70ef0058-object_0",Detalle!$B$2:$B$1370,$A39,Detalle!$C$2:$C$1370,$B39) -> 33.674809 | J39: =SUMIFS(Detalle!$I$2:$I$1370,Detalle!$A$2:$A$1370,"80c13944-object_3",Detalle!$B$2:$B$1370,$A39,Detalle!$C$2:$C$1370,$B39) -> 32.407294 | K39: =SUMIFS(Detalle!$I$2:$I$1370,Detalle!$A$2:$A$1370,"fba550bc-object_1",Detalle!$B$2:$B$1370,$A39,Detalle!$C$2:$C$1370,$B39) -> 39.526692 | L39: =SUMIFS(Detalle!$I$2:$I$1370,Detalle!$A$2:$A$1370,"38448021-object_5",Detalle!$B$2:$B$1370,$A39,Detalle!$C$2:$C$1370,$B39) -> 60.423028 | M39: =SUMIFS(Detalle!$I$2:$I$1370,Detalle!$A$2:$A$1370,"6e95d62d-object_4",Detalle!$B$2:$B$1370,$A39,Detalle!$C$2:$C$1370,$B39) -> 120.18103
A40: cabeza | B40: contorno a 75% de la cabeza | C40: =SUMIFS(Detalle!$I$2:$I$1370,Detalle!$A$2:$A$1370,"2a3facb9-object_2",Detalle!$B$2:$B$1370,$A40,Detalle!$C$2:$C$1370,$B40) -> 145.45233 | D40: =SUMIFS(Detalle!$I$2:$I$1370,Detalle!$A$2:$A$1370,"2f639739-object_1",Detalle!$B$2:$B$1370,$A40,Detalle!$C$2:$C$1370,$B40) -> 132.13218 | E40: =SUMIFS(Detalle!$I$2:$I$1370,Detalle!$A$2:$A$1370,"5dc9e0d5-object_0",Detalle!$B$2:$B$1370,$A40,Detalle!$C$2:$C$1370,$B40) -> 148.47378 | G40: =SUMIFS(Detalle!$I$2:$I$1370,Detalle!$A$2:$A$1370,"2b65e967-object_0-1",Detalle!$B$2:$B$1370,$A40,Detalle!$C$2:$C$1370,$B40) -> 161.85965 | H40: =SUMIFS(Detalle!$I$2:$I$1370,Detalle!$A$2:$A$1370,"5ed925a3-object_2",Detalle!$B$2:$B$1370,$A40,Detalle!$C$2:$C$1370,$B40) -> 136.61056 | I40: =SUMIFS(Detalle!$I$2:$I$1370,Detalle!$A$2:$A$1370,"70ef0058-object_0",Detalle!$B$2:$B$1370,$A40,Detalle!$C$2:$C$1370,$B40) -> 179.46082 | J40: =SUMIFS(Detalle!$I$2:$I$1370,Detalle!$A$2:$A$1370,"80c13944-object_3",Detalle!$B$2:$B$1370,$A40,Detalle!$C$2:$C$1370,$B40) -> 153.43656 | K40: =SUMIFS(Detalle!$I$2:$I$1370,Detalle!$A$2:$A$1370,"fba550bc-object_1",Detalle!$B$2:$B$1370,$A40,Detalle!$C$2:$C$1370,$B40) -> 161.36834 | L40: =SUMIFS(Detalle!$I$2:$I$1370,Detalle!$A$2:$A$1370,"38448021-object_5",Detalle!$B$2:$B$1370,$A40,Detalle!$C$2:$C$1370,$B40) -> 271.42396 | M40: =SUMIFS(Detalle!$I$2:$I$1370,Detalle!$A$2:$A$1370,"6e95d62d-object_4",Detalle!$B$2:$B$1370,$A40,Detalle!$C$2:$C$1370,$B40) -> 692.69682
A41: orejas | B41: oreja izq altura centro | C41: =SUMIFS(Detalle!$I$2:$I$1370,Detalle!$A$2:$A$1370,"2a3facb9-object_2",Detalle!$B$2:$B$1370,$A41,Detalle!$C$2:$C$1370,$B41) -> 67.782769 | D41: =SUMIFS(Detalle!$I$2:$I$1370,Detalle!$A$2:$A$1370,"2f639739-object_1",Detalle!$B$2:$B$1370,$A41,Detalle!$C$2:$C$1370,$B41) -> 67.637189 | E41: =SUMIFS(Detalle!$I$2:$I$1370,Detalle!$A$2:$A$1370,"5dc9e0d5-object_0",Detalle!$B$2:$B$1370,$A41,Detalle!$C$2:$C$1370,$B41) -> 67.512072 | F41: =SUMIFS(Detalle!$I$2:$I$1370,Detalle!$A$2:$A$1370,"a501b501-object_3",Detalle!$B$2:$B$1370,$A41,Detalle!$C$2:$C$1370,$B41) -> 55.152648 | G41: =SUMIFS(Detalle!$I$2:$I$1370,Detalle!$A$2:$A$1370,"2b65e967-object_0-1",Detalle!$B$2:$B$1370,$A41,Detalle!$C$2:$C$1370,$B41) -> 67.758522 | H41: =SUMIFS(Detalle!$I$2:$I$1370,Detalle!$A$2:$A$1370,"5ed925a3-object_2",Detalle!$B$2:$B$1370,$A41,Detalle!$C$2:$C$1370,$B41) -> 67.608969 | I41: =SUMIFS(Detalle!$I$2:$I$1370,Detalle!$A$2:$A$1370,"70ef0058-object_0",Detalle!$B$2:$B$1370,$A41,Detalle!$C$2:$C$1370,$B41) -> 66.285813 | J41: =SUMIFS(Detalle!$I$2:$I$1370,Detalle!$A$2:$A$1370,"80c13944-object_3",Detalle!$B$2:$B$1370,$A41,Detalle!$C$2:$C$1370,$B41) -> 68.166936 | K41: =SUMIFS(Detalle!$I$2:$I$1370,Detalle!$A$2:$A$1370,"fba550bc-object_1",Detalle!$B$2:$B$1370,$A41,Detalle!$C$2:$C$1370,$B41) -> 68.761995 | L41: =SUMIFS(Detalle!$I$2:$I$1370,Detalle!$A$2:$A$1370,"38448021-object_5",Detalle!$B$2:$B$1370,$A41,Detalle!$C$2:$C$1370,$B41) -> 54.573922 | M41: =SUMIFS(Detalle!$I$2:$I$1370,Detalle!$A$2:$A$1370,"6e95d62d-object_4",Detalle!$B$2:$B$1370,$A41,Detalle!$C$2:$C$1370,$B41) -> 49.793329
A42: orejas | B42: oreja izq saliente X | C42: =SUMIFS(Detalle!$I$2:$I$1370,Detalle!$A$2:$A$1370,"2a3facb9-object_2",Detalle!$B$2:$B$1370,$A42,Detalle!$C$2:$C$1370,$B42) -> 24.832718 | D42: =SUMIFS(Detalle!$I$2:$I$1370,Detalle!$A$2:$A$1370,"2f639739-object_1",Detalle!$B$2:$B$1370,$A42,Detalle!$C$2:$C$1370,$B42) -> 24.60244 | E42: =SUMIFS(Detalle!$I$2:$I$1370,Detalle!$A$2:$A$1370,"5dc9e0d5-object_0",Detalle!$B$2:$B$1370,$A42,Detalle!$C$2:$C$1370,$B42) -> 26.570446 | F42: =SUMIFS(Detalle!$I$2:$I$1370,Detalle!$A$2:$A$1370,"a501b501-object_3",Detalle!$B$2:$B$1370,$A42,Detalle!$C$2:$C$1370,$B42) -> 15.310997 | G42: =SUMIFS(Detalle!$I$2:$I$1370,Detalle!$A$2:$A$1370,"2b65e967-object_0-1",Detalle!$B$2:$B$1370,$A42,Detalle!$C$2:$C$1370,$B42) -> 25.070463 | H42: =SUMIFS(Detalle!$I$2:$I$1370,Detalle!$A$2:$A$1370,"5ed925a3-object_2",Detalle!$B$2:$B$1370,$A42,Detalle!$C$2:$C$1370,$B42) -> 23.166657 | I42: =SUMIFS(Detalle!$I$2:$I$1370,Detalle!$A$2:$A$1370,"70ef0058-object_0",Detalle!$B$2:$B$1370,$A42,Detalle!$C$2:$C$1370,$B42) -> 27.973611 | J42: =SUMIFS(Detalle!$I$2:$I$1370,Detalle!$A$2:$A$1370,"80c13944-object_3",Detalle!$B$2:$B$1370,$A42,Detalle!$C$2:$C$1370,$B42) -> 24.612134 | K42: =SUMIFS(Detalle!$I$2:$I$1370,Detalle!$A$2:$A$1370,"fba550bc-object_1",Detalle!$B$2:$B$1370,$A42,Detalle!$C$2:$C$1370,$B42) -> 23.412768 | L42: =SUMIFS(Detalle!$I$2:$I$1370,Detalle!$A$2:$A$1370,"38448021-object_5",Detalle!$B$2:$B$1370,$A42,Detalle!$C$2:$C$1370,$B42) -> 45.792665 | M42: =SUMIFS(Detalle!$I$2:$I$1370,Detalle!$A$2:$A$1370,"6e95d62d-object_4",Detalle!$B$2:$B$1370,$A42,Detalle!$C$2:$C$1370,$B42) -> 63.353289
A43: orejas | B43: oreja der altura centro | C43: =SUMIFS(Detalle!$I$2:$I$1370,Detalle!$A$2:$A$1370,"2a3facb9-object_2",Detalle!$B$2:$B$1370,$A43,Detalle!$C$2:$C$1370,$B43) -> 68.45242 | D43: =SUMIFS(Detalle!$I$2:$I$1370,Detalle!$A$2:$A$1370,"2f639739-object_1",Detalle!$B$2:$B$1370,$A43,Detalle!$C$2:$C$1370,$B43) -> 66.225105 | E43: =SUMIFS(Detalle!$I$2:$I$1370,Detalle!$A$2:$A$1370,"5dc9e0d5-object_0",Detalle!$B$2:$B$1370,$A43,Detalle!$C$2:$C$1370,$B43) -> 67.586161 | F43: =SUMIFS(Detalle!$I$2:$I$1370,Detalle!$A$2:$A$1370,"a501b501-object_3",Detalle!$B$2:$B$1370,$A43,Detalle!$C$2:$C$1370,$B43) -> 56.407586 | G43: =SUMIFS(Detalle!$I$2:$I$1370,Detalle!$A$2:$A$1370,"2b65e967-object_0-1",Detalle!$B$2:$B$1370,$A43,Detalle!$C$2:$C$1370,$B43) -> 67.373834 | H43: =SUMIFS(Detalle!$I$2:$I$1370,Detalle!$A$2:$A$1370,"5ed925a3-object_2",Detalle!$B$2:$B$1370,$A43,Detalle!$C$2:$C$1370,$B43) -> 67.443792 | I43: =SUMIFS(Detalle!$I$2:$I$1370,Detalle!$A$2:$A$1370,"70ef0058-object_0",Detalle!$B$2:$B$1370,$A43,Detalle!$C$2:$C$1370,$B43) -> 66.312432 | J43: =SUMIFS(Detalle!$I$2:$I$1370,Detalle!$A$2:$A$1370,"80c13944-object_3",Detalle!$B$2:$B$1370,$A43,Detalle!$C$2:$C$1370,$B43) -> 68.929785 | K43: =SUMIFS(Detalle!$I$2:$I$1370,Detalle!$A$2:$A$1370,"fba550bc-object_1",Detalle!$B$2:$B$1370,$A43,Detalle!$C$2:$C$1370,$B43) -> 68.765798 | L43: =SUMIFS(Detalle!$I$2:$I$1370,Detalle!$A$2:$A$1370,"38448021-object_5",Detalle!$B$2:$B$1370,$A43,Detalle!$C$2:$C$1370,$B43) -> 53.778908 | M43: =SUMIFS(Detalle!$I$2:$I$1370,Detalle!$A$2:$A$1370,"6e95d62d-object_4",Detalle!$B$2:$B$1370,$A43,Detalle!$C$2:$C$1370,$B43) -> 47.425846
A44: orejas | B44: oreja der saliente X | C44: =SUMIFS(Detalle!$I$2:$I$1370,Detalle!$A$2:$A$1370,"2a3facb9-object_2",Detalle!$B$2:$B$1370,$A44,Detalle!$C$2:$C$1370,$B44) -> 24.296203 | D44: =SUMIFS(Detalle!$I$2:$I$1370,Detalle!$A$2:$A$1370,"2f639739-object_1",Detalle!$B$2:$B$1370,$A44,Detalle!$C$2:$C$1370,$B44) -> 21.729711 | E44: =SUMIFS(Detalle!$I$2:$I$1370,Detalle!$A$2:$A$1370,"5dc9e0d5-object_0",Detalle!$B$2:$B$1370,$A44,Detalle!$C$2:$C$1370,$B44) -> 24.784197 | F44: =SUMIFS(Detalle!$I$2:$I$1370,Detalle!$A$2:$A$1370,"a501b501-object_3",Detalle!$B$2:$B$1370,$A44,Detalle!$C$2:$C$1370,$B44) -> 15.99404 | G44: =SUMIFS(Detalle!$I$2:$I$1370,Detalle!$A$2:$A$1370,"2b65e967-object_0-1",Detalle!$B$2:$B$1370,$A44,Detalle!$C$2:$C$1370,$B44) -> 25.070463 | H44: =SUMIFS(Detalle!$I$2:$I$1370,Detalle!$A$2:$A$1370,"5ed925a3-object_2",Detalle!$B$2:$B$1370,$A44,Detalle!$C$2:$C$1370,$B44) -> 23.036603 | I44: =SUMIFS(Detalle!$I$2:$I$1370,Detalle!$A$2:$A$1370,"70ef0058-object_0",Detalle!$B$2:$B$1370,$A44,Detalle!$C$2:$C$1370,$B44) -> 29.034565 | J44: =SUMIFS(Detalle!$I$2:$I$1370,Detalle!$A$2:$A$1370,"80c13944-object_3",Detalle!$B$2:$B$1370,$A44,Detalle!$C$2:$C$1370,$B44) -> 24.612134 | K44: =SUMIFS(Detalle!$I$2:$I$1370,Detalle!$A$2:$A$1370,"fba550bc-object_1",Detalle!$B$2:$B$1370,$A44,Detalle!$C$2:$C$1370,$B44) -> 23.412768 | L44: =SUMIFS(Detalle!$I$2:$I$1370,Detalle!$A$2:$A$1370,"38448021-object_5",Detalle!$B$2:$B$1370,$A44,Detalle!$C$2:$C$1370,$B44) -> 43.026735 | M44: =SUMIFS(Detalle!$I$2:$I$1370,Detalle!$A$2:$A$1370,"6e95d62d-object_4",Detalle!$B$2:$B$1370,$A44,Detalle!$C$2:$C$1370,$B44) -> 63.830868
A45: chaleco | B45: borde superior (alto) | C45: =SUMIFS(Detalle!$I$2:$I$1370,Detalle!$A$2:$A$1370,"2a3facb9-object_2",Detalle!$B$2:$B$1370,$A45,Detalle!$C$2:$C$1370,$B45) -> 53.145832 | D45: =SUMIFS(Detalle!$I$2:$I$1370,Detalle!$A$2:$A$1370,"2f639739-object_1",Detalle!$B$2:$B$1370,$A45,Detalle!$C$2:$C$1370,$B45) -> 50.446523 | E45: =SUMIFS(Detalle!$I$2:$I$1370,Detalle!$A$2:$A$1370,"5dc9e0d5-object_0",Detalle!$B$2:$B$1370,$A45,Detalle!$C$2:$C$1370,$B45) -> 51.868189 | F45: =SUMIFS(Detalle!$I$2:$I$1370,Detalle!$A$2:$A$1370,"a501b501-object_3",Detalle!$B$2:$B$1370,$A45,Detalle!$C$2:$C$1370,$B45) -> 38.440416 | G45: =SUMIFS(Detalle!$I$2:$I$1370,Detalle!$A$2:$A$1370,"2b65e967-object_0-1",Detalle!$B$2:$B$1370,$A45,Detalle!$C$2:$C$1370,$B45) -> 53.735479 | H45: =SUMIFS(Detalle!$I$2:$I$1370,Detalle!$A$2:$A$1370,"5ed925a3-object_2",Detalle!$B$2:$B$1370,$A45,Detalle!$C$2:$C$1370,$B45) -> 52.23035 | I45: =SUMIFS(Detalle!$I$2:$I$1370,Detalle!$A$2:$A$1370,"70ef0058-object_0",Detalle!$B$2:$B$1370,$A45,Detalle!$C$2:$C$1370,$B45) -> 48.709734 | J45: =SUMIFS(Detalle!$I$2:$I$1370,Detalle!$A$2:$A$1370,"80c13944-object_3",Detalle!$B$2:$B$1370,$A45,Detalle!$C$2:$C$1370,$B45) -> 53.572796 | K45: =SUMIFS(Detalle!$I$2:$I$1370,Detalle!$A$2:$A$1370,"fba550bc-object_1",Detalle!$B$2:$B$1370,$A45,Detalle!$C$2:$C$1370,$B45) -> 53.595837 | L45: =SUMIFS(Detalle!$I$2:$I$1370,Detalle!$A$2:$A$1370,"38448021-object_5",Detalle!$B$2:$B$1370,$A45,Detalle!$C$2:$C$1370,$B45) -> 30.679784
A46: chaleco | B46: borde inferior (alto) | C46: =SUMIFS(Detalle!$I$2:$I$1370,Detalle!$A$2:$A$1370,"2a3facb9-object_2",Detalle!$B$2:$B$1370,$A46,Detalle!$C$2:$C$1370,$B46) -> 27.55007 | D46: =SUMIFS(Detalle!$I$2:$I$1370,Detalle!$A$2:$A$1370,"2f639739-object_1",Detalle!$B$2:$B$1370,$A46,Detalle!$C$2:$C$1370,$B46) -> 26.600114 | F46: =SUMIFS(Detalle!$I$2:$I$1370,Detalle!$A$2:$A$1370,"a501b501-object_3",Detalle!$B$2:$B$1370,$A46,Detalle!$C$2:$C$1370,$B46) -> 19.949801 | G46: =SUMIFS(Detalle!$I$2:$I$1370,Detalle!$A$2:$A$1370,"2b65e967-object_0-1",Detalle!$B$2:$B$1370,$A46,Detalle!$C$2:$C$1370,$B46) -> 29.449629 | H46: =SUMIFS(Detalle!$I$2:$I$1370,Detalle!$A$2:$A$1370,"5ed925a3-object_2",Detalle!$B$2:$B$1370,$A46,Detalle!$C$2:$C$1370,$B46) -> 30.400304 | I46: =SUMIFS(Detalle!$I$2:$I$1370,Detalle!$A$2:$A$1370,"70ef0058-object_0",Detalle!$B$2:$B$1370,$A46,Detalle!$C$2:$C$1370,$B46) -> 27.54961 | J46: =SUMIFS(Detalle!$I$2:$I$1370,Detalle!$A$2:$A$1370,"80c13944-object_3",Detalle!$B$2:$B$1370,$A46,Detalle!$C$2:$C$1370,$B46) -> 30.399695 | K46: =SUMIFS(Detalle!$I$2:$I$1370,Detalle!$A$2:$A$1370,"fba550bc-object_1",Detalle!$B$2:$B$1370,$A46,Detalle!$C$2:$C$1370,$B46) -> 27.549857
A47: chaleco | B47: largo vertical | C47: =SUMIFS(Detalle!$I$2:$I$1370,Detalle!$A$2:$A$1370,"2a3facb9-object_2",Detalle!$B$2:$B$1370,$A47,Detalle!$C$2:$C$1370,$B47) -> 25.595762 | D47: =SUMIFS(Detalle!$I$2:$I$1370,Detalle!$A$2:$A$1370,"2f639739-object_1",Detalle!$B$2:$B$1370,$A47,Detalle!$C$2:$C$1370,$B47) -> 23.846408 | F47: =SUMIFS(Detalle!$I$2:$I$1370,Detalle!$A$2:$A$1370,"a501b501-object_3",Detalle!$B$2:$B$1370,$A47,Detalle!$C$2:$C$1370,$B47) -> 18.490615 | G47: =SUMIFS(Detalle!$I$2:$I$1370,Detalle!$A$2:$A$1370,"2b65e967-object_0-1",Detalle!$B$2:$B$1370,$A47,Detalle!$C$2:$C$1370,$B47) -> 24.28585 | H47: =SUMIFS(Detalle!$I$2:$I$1370,Detalle!$A$2:$A$1370,"5ed925a3-object_2",Detalle!$B$2:$B$1370,$A47,Detalle!$C$2:$C$1370,$B47) -> 21.830995 | I47: =SUMIFS(Detalle!$I$2:$I$1370,Detalle!$A$2:$A$1370,"70ef0058-object_0",Detalle!$B$2:$B$1370,$A47,Detalle!$C$2:$C$1370,$B47) -> 21.160124 | J47: =SUMIFS(Detalle!$I$2:$I$1370,Detalle!$A$2:$A$1370,"80c13944-object_3",Detalle!$B$2:$B$1370,$A47,Detalle!$C$2:$C$1370,$B47) -> 23.173101 | K47: =SUMIFS(Detalle!$I$2:$I$1370,Detalle!$A$2:$A$1370,"fba550bc-object_1",Detalle!$B$2:$B$1370,$A47,Detalle!$C$2:$C$1370,$B47) -> 26.04598
A48: chaleco | B48: ancho (frente) | C48: =SUMIFS(Detalle!$I$2:$I$1370,Detalle!$A$2:$A$1370,"2a3facb9-object_2",Detalle!$B$2:$B$1370,$A48,Detalle!$C$2:$C$1370,$B48) -> 28.448236 | D48: =SUMIFS(Detalle!$I$2:$I$1370,Detalle!$A$2:$A$1370,"2f639739-object_1",Detalle!$B$2:$B$1370,$A48,Detalle!$C$2:$C$1370,$B48) -> 22.676178 | E48: =SUMIFS(Detalle!$I$2:$I$1370,Detalle!$A$2:$A$1370,"5dc9e0d5-object_0",Detalle!$B$2:$B$1370,$A48,Detalle!$C$2:$C$1370,$B48) -> 26.746026 | F48: =SUMIFS(Detalle!$I$2:$I$1370,Detalle!$A$2:$A$1370,"a501b501-object_3",Detalle!$B$2:$B$1370,$A48,Detalle!$C$2:$C$1370,$B48) -> 17.511175 | G48: =SUMIFS(Detalle!$I$2:$I$1370,Detalle!$A$2:$A$1370,"2b65e967-object_0-1",Detalle!$B$2:$B$1370,$A48,Detalle!$C$2:$C$1370,$B48) -> 27.580461 | H48: =SUMIFS(Detalle!$I$2:$I$1370,Detalle!$A$2:$A$1370,"5ed925a3-object_2",Detalle!$B$2:$B$1370,$A48,Detalle!$C$2:$C$1370,$B48) -> 24.43207 | I48: =SUMIFS(Detalle!$I$2:$I$1370,Detalle!$A$2:$A$1370,"70ef0058-object_0",Detalle!$B$2:$B$1370,$A48,Detalle!$C$2:$C$1370,$B48) -> 26.676891 | J48: =SUMIFS(Detalle!$I$2:$I$1370,Detalle!$A$2:$A$1370,"80c13944-object_3",Detalle!$B$2:$B$1370,$A48,Detalle!$C$2:$C$1370,$B48) -> 22.725486 | K48: =SUMIFS(Detalle!$I$2:$I$1370,Detalle!$A$2:$A$1370,"fba550bc-object_1",Detalle!$B$2:$B$1370,$A48,Detalle!$C$2:$C$1370,$B48) -> 25.40051 | L48: =SUMIFS(Detalle!$I$2:$I$1370,Detalle!$A$2:$A$1370,"38448021-object_5",Detalle!$B$2:$B$1370,$A48,Detalle!$C$2:$C$1370,$B48) -> 31.451053
A49: chaleco | B49: fondo | C49: =SUMIFS(Detalle!$I$2:$I$1370,Detalle!$A$2:$A$1370,"2a3facb9-object_2",Detalle!$B$2:$B$1370,$A49,Detalle!$C$2:$C$1370,$B49) -> 24.540615 | D49: =SUMIFS(Detalle!$I$2:$I$1370,Detalle!$A$2:$A$1370,"2f639739-object_1",Detalle!$B$2:$B$1370,$A49,Detalle!$C$2:$C$1370,$B49) -> 19.638723 | E49: =SUMIFS(Detalle!$I$2:$I$1370,Detalle!$A$2:$A$1370,"5dc9e0d5-object_0",Detalle!$B$2:$B$1370,$A49,Detalle!$C$2:$C$1370,$B49) -> 21.998259 | F49: =SUMIFS(Detalle!$I$2:$I$1370,Detalle!$A$2:$A$1370,"a501b501-object_3",Detalle!$B$2:$B$1370,$A49,Detalle!$C$2:$C$1370,$B49) -> 15.733743 | G49: =SUMIFS(Detalle!$I$2:$I$1370,Detalle!$A$2:$A$1370,"2b65e967-object_0-1",Detalle!$B$2:$B$1370,$A49,Detalle!$C$2:$C$1370,$B49) -> 18.993525 | H49: =SUMIFS(Detalle!$I$2:$I$1370,Detalle!$A$2:$A$1370,"5ed925a3-object_2",Detalle!$B$2:$B$1370,$A49,Detalle!$C$2:$C$1370,$B49) -> 16.33836 | I49: =SUMIFS(Detalle!$I$2:$I$1370,Detalle!$A$2:$A$1370,"70ef0058-object_0",Detalle!$B$2:$B$1370,$A49,Detalle!$C$2:$C$1370,$B49) -> 20.22466 | J49: =SUMIFS(Detalle!$I$2:$I$1370,Detalle!$A$2:$A$1370,"80c13944-object_3",Detalle!$B$2:$B$1370,$A49,Detalle!$C$2:$C$1370,$B49) -> 20.764554 | K49: =SUMIFS(Detalle!$I$2:$I$1370,Detalle!$A$2:$A$1370,"fba550bc-object_1",Detalle!$B$2:$B$1370,$A49,Detalle!$C$2:$C$1370,$B49) -> 20.065643 | L49: =SUMIFS(Detalle!$I$2:$I$1370,Detalle!$A$2:$A$1370,"38448021-object_5",Detalle!$B$2:$B$1370,$A49,Detalle!$C$2:$C$1370,$B49) -> 19.844027
A50: pantalón | B50: cintura / borde superior visible (alto) | C50: =SUMIFS(Detalle!$I$2:$I$1370,Detalle!$A$2:$A$1370,"2a3facb9-object_2",Detalle!$B$2:$B$1370,$A50,Detalle!$C$2:$C$1370,$B50) -> 33.193417 | D50: =SUMIFS(Detalle!$I$2:$I$1370,Detalle!$A$2:$A$1370,"2f639739-object_1",Detalle!$B$2:$B$1370,$A50,Detalle!$C$2:$C$1370,$B50) -> 29.468082 | E50: =SUMIFS(Detalle!$I$2:$I$1370,Detalle!$A$2:$A$1370,"5dc9e0d5-object_0",Detalle!$B$2:$B$1370,$A50,Detalle!$C$2:$C$1370,$B50) -> 31.753611 | F50: =SUMIFS(Detalle!$I$2:$I$1370,Detalle!$A$2:$A$1370,"a501b501-object_3",Detalle!$B$2:$B$1370,$A50,Detalle!$C$2:$C$1370,$B50) -> 24.084159 | G50: =SUMIFS(Detalle!$I$2:$I$1370,Detalle!$A$2:$A$1370,"2b65e967-object_0-1",Detalle!$B$2:$B$1370,$A50,Detalle!$C$2:$C$1370,$B50) -> 32.545229 | H50: =SUMIFS(Detalle!$I$2:$I$1370,Detalle!$A$2:$A$1370,"5ed925a3-object_2",Detalle!$B$2:$B$1370,$A50,Detalle!$C$2:$C$1370,$B50) -> 31.563193 | I50: =SUMIFS(Detalle!$I$2:$I$1370,Detalle!$A$2:$A$1370,"70ef0058-object_0",Detalle!$B$2:$B$1370,$A50,Detalle!$C$2:$C$1370,$B50) -> 30.876022 | J50: =SUMIFS(Detalle!$I$2:$I$1370,Detalle!$A$2:$A$1370,"80c13944-object_3",Detalle!$B$2:$B$1370,$A50,Detalle!$C$2:$C$1370,$B50) -> 31.840633 | K50: =SUMIFS(Detalle!$I$2:$I$1370,Detalle!$A$2:$A$1370,"fba550bc-object_1",Detalle!$B$2:$B$1370,$A50,Detalle!$C$2:$C$1370,$B50) -> 38.545655 | L50: =SUMIFS(Detalle!$I$2:$I$1370,Detalle!$A$2:$A$1370,"38448021-object_5",Detalle!$B$2:$B$1370,$A50,Detalle!$C$2:$C$1370,$B50) -> 29.852475
A51: pantalón | B51: bastilla / borde inferior (alto) | C51: =SUMIFS(Detalle!$I$2:$I$1370,Detalle!$A$2:$A$1370,"2a3facb9-object_2",Detalle!$B$2:$B$1370,$A51,Detalle!$C$2:$C$1370,$B51) -> 7.2171267 | D51: =SUMIFS(Detalle!$I$2:$I$1370,Detalle!$A$2:$A$1370,"2f639739-object_1",Detalle!$B$2:$B$1370,$A51,Detalle!$C$2:$C$1370,$B51) -> 6.6186066 | E51: =SUMIFS(Detalle!$I$2:$I$1370,Detalle!$A$2:$A$1370,"5dc9e0d5-object_0",Detalle!$B$2:$B$1370,$A51,Detalle!$C$2:$C$1370,$B51) -> 7.1876202 | F51: =SUMIFS(Detalle!$I$2:$I$1370,Detalle!$A$2:$A$1370,"a501b501-object_3",Detalle!$B$2:$B$1370,$A51,Detalle!$C$2:$C$1370,$B51) -> 4.2797072 | G51: =SUMIFS(Detalle!$I$2:$I$1370,Detalle!$A$2:$A$1370,"2b65e967-object_0-1",Detalle!$B$2:$B$1370,$A51,Detalle!$C$2:$C$1370,$B51) -> 7.4252523 | H51: =SUMIFS(Detalle!$I$2:$I$1370,Detalle!$A$2:$A$1370,"5ed925a3-object_2",Detalle!$B$2:$B$1370,$A51,Detalle!$C$2:$C$1370,$B51) -> 7.3371205 | I51: =SUMIFS(Detalle!$I$2:$I$1370,Detalle!$A$2:$A$1370,"70ef0058-object_0",Detalle!$B$2:$B$1370,$A51,Detalle!$C$2:$C$1370,$B51) -> 6.1689299 | J51: =SUMIFS(Detalle!$I$2:$I$1370,Detalle!$A$2:$A$1370,"80c13944-object_3",Detalle!$B$2:$B$1370,$A51,Detalle!$C$2:$C$1370,$B51) -> 6.5789817 | K51: =SUMIFS(Detalle!$I$2:$I$1370,Detalle!$A$2:$A$1370,"fba550bc-object_1",Detalle!$B$2:$B$1370,$A51,Detalle!$C$2:$C$1370,$B51) -> 7.3444739 | L51: =SUMIFS(Detalle!$I$2:$I$1370,Detalle!$A$2:$A$1370,"38448021-object_5",Detalle!$B$2:$B$1370,$A51,Detalle!$C$2:$C$1370,$B51) -> 19.594219
A52: pantalón | B52: largo total visible | C52: =SUMIFS(Detalle!$I$2:$I$1370,Detalle!$A$2:$A$1370,"2a3facb9-object_2",Detalle!$B$2:$B$1370,$A52,Detalle!$C$2:$C$1370,$B52) -> 25.975297 | D52: =SUMIFS(Detalle!$I$2:$I$1370,Detalle!$A$2:$A$1370,"2f639739-object_1",Detalle!$B$2:$B$1370,$A52,Detalle!$C$2:$C$1370,$B52) -> 22.850427 | E52: =SUMIFS(Detalle!$I$2:$I$1370,Detalle!$A$2:$A$1370,"5dc9e0d5-object_0",Detalle!$B$2:$B$1370,$A52,Detalle!$C$2:$C$1370,$B52) -> 24.565991 | F52: =SUMIFS(Detalle!$I$2:$I$1370,Detalle!$A$2:$A$1370,"a501b501-object_3",Detalle!$B$2:$B$1370,$A52,Detalle!$C$2:$C$1370,$B52) -> 19.804452 | G52: =SUMIFS(Detalle!$I$2:$I$1370,Detalle!$A$2:$A$1370,"2b65e967-object_0-1",Detalle!$B$2:$B$1370,$A52,Detalle!$C$2:$C$1370,$B52) -> 25.119977 | H52: =SUMIFS(Detalle!$I$2:$I$1370,Detalle!$A$2:$A$1370,"5ed925a3-object_2",Detalle!$B$2:$B$1370,$A52,Detalle!$C$2:$C$1370,$B52) -> 24.226073 | I52: =SUMIFS(Detalle!$I$2:$I$1370,Detalle!$A$2:$A$1370,"70ef0058-object_0",Detalle!$B$2:$B$1370,$A52,Detalle!$C$2:$C$1370,$B52) -> 24.707092 | J52: =SUMIFS(Detalle!$I$2:$I$1370,Detalle!$A$2:$A$1370,"80c13944-object_3",Detalle!$B$2:$B$1370,$A52,Detalle!$C$2:$C$1370,$B52) -> 25.261652 | K52: =SUMIFS(Detalle!$I$2:$I$1370,Detalle!$A$2:$A$1370,"fba550bc-object_1",Detalle!$B$2:$B$1370,$A52,Detalle!$C$2:$C$1370,$B52) -> 31.201181 | L52: =SUMIFS(Detalle!$I$2:$I$1370,Detalle!$A$2:$A$1370,"38448021-object_5",Detalle!$B$2:$B$1370,$A52,Detalle!$C$2:$C$1370,$B52) -> 10.258256
A53: pantalón | B53: ancho máx | C53: =SUMIFS(Detalle!$I$2:$I$1370,Detalle!$A$2:$A$1370,"2a3facb9-object_2",Detalle!$B$2:$B$1370,$A53,Detalle!$C$2:$C$1370,$B53) -> 35.609724 | D53: =SUMIFS(Detalle!$I$2:$I$1370,Detalle!$A$2:$A$1370,"2f639739-object_1",Detalle!$B$2:$B$1370,$A53,Detalle!$C$2:$C$1370,$B53) -> 24.361538 | E53: =SUMIFS(Detalle!$I$2:$I$1370,Detalle!$A$2:$A$1370,"5dc9e0d5-object_0",Detalle!$B$2:$B$1370,$A53,Detalle!$C$2:$C$1370,$B53) -> 36.104547 | F53: =SUMIFS(Detalle!$I$2:$I$1370,Detalle!$A$2:$A$1370,"a501b501-object_3",Detalle!$B$2:$B$1370,$A53,Detalle!$C$2:$C$1370,$B53) -> 24.245658 | G53: =SUMIFS(Detalle!$I$2:$I$1370,Detalle!$A$2:$A$1370,"2b65e967-object_0-1",Detalle!$B$2:$B$1370,$A53,Detalle!$C$2:$C$1370,$B53) -> 32.808037 | H53: =SUMIFS(Detalle!$I$2:$I$1370,Detalle!$A$2:$A$1370,"5ed925a3-object_2",Detalle!$B$2:$B$1370,$A53,Detalle!$C$2:$C$1370,$B53) -> 36.589724 | I53: =SUMIFS(Detalle!$I$2:$I$1370,Detalle!$A$2:$A$1370,"70ef0058-object_0",Detalle!$B$2:$B$1370,$A53,Detalle!$C$2:$C$1370,$B53) -> 36.041039 | J53: =SUMIFS(Detalle!$I$2:$I$1370,Detalle!$A$2:$A$1370,"80c13944-object_3",Detalle!$B$2:$B$1370,$A53,Detalle!$C$2:$C$1370,$B53) -> 34.03204 | K53: =SUMIFS(Detalle!$I$2:$I$1370,Detalle!$A$2:$A$1370,"fba550bc-object_1",Detalle!$B$2:$B$1370,$A53,Detalle!$C$2:$C$1370,$B53) -> 19.898334 | L53: =SUMIFS(Detalle!$I$2:$I$1370,Detalle!$A$2:$A$1370,"38448021-object_5",Detalle!$B$2:$B$1370,$A53,Detalle!$C$2:$C$1370,$B53) -> 8.3310337
A54: pantalón | B54: fondo máx | C54: =SUMIFS(Detalle!$I$2:$I$1370,Detalle!$A$2:$A$1370,"2a3facb9-object_2",Detalle!$B$2:$B$1370,$A54,Detalle!$C$2:$C$1370,$B54) -> 17.616585 | D54: =SUMIFS(Detalle!$I$2:$I$1370,Detalle!$A$2:$A$1370,"2f639739-object_1",Detalle!$B$2:$B$1370,$A54,Detalle!$C$2:$C$1370,$B54) -> 16.548897 | E54: =SUMIFS(Detalle!$I$2:$I$1370,Detalle!$A$2:$A$1370,"5dc9e0d5-object_0",Detalle!$B$2:$B$1370,$A54,Detalle!$C$2:$C$1370,$B54) -> 17.181477 | F54: =SUMIFS(Detalle!$I$2:$I$1370,Detalle!$A$2:$A$1370,"a501b501-object_3",Detalle!$B$2:$B$1370,$A54,Detalle!$C$2:$C$1370,$B54) -> 12.788772 | G54: =SUMIFS(Detalle!$I$2:$I$1370,Detalle!$A$2:$A$1370,"2b65e967-object_0-1",Detalle!$B$2:$B$1370,$A54,Detalle!$C$2:$C$1370,$B54) -> 19.899067 | H54: =SUMIFS(Detalle!$I$2:$I$1370,Detalle!$A$2:$A$1370,"5ed925a3-object_2",Detalle!$B$2:$B$1370,$A54,Detalle!$C$2:$C$1370,$B54) -> 17.492705 | I54: =SUMIFS(Detalle!$I$2:$I$1370,Detalle!$A$2:$A$1370,"70ef0058-object_0",Detalle!$B$2:$B$1370,$A54,Detalle!$C$2:$C$1370,$B54) -> 19.598165 | J54: =SUMIFS(Detalle!$I$2:$I$1370,Detalle!$A$2:$A$1370,"80c13944-object_3",Detalle!$B$2:$B$1370,$A54,Detalle!$C$2:$C$1370,$B54) -> 18.721717 | K54: =SUMIFS(Detalle!$I$2:$I$1370,Detalle!$A$2:$A$1370,"fba550bc-object_1",Detalle!$B$2:$B$1370,$A54,Detalle!$C$2:$C$1370,$B54) -> 17.036974 | L54: =SUMIFS(Detalle!$I$2:$I$1370,Detalle!$A$2:$A$1370,"38448021-object_5",Detalle!$B$2:$B$1370,$A54,Detalle!$C$2:$C$1370,$B54) -> 0.83395823
A55: piernas | B55: entrepierna (alto) | C55: =SUMIFS(Detalle!$I$2:$I$1370,Detalle!$A$2:$A$1370,"2a3facb9-object_2",Detalle!$B$2:$B$1370,$A55,Detalle!$C$2:$C$1370,$B55) -> 22.082579 | D55: =SUMIFS(Detalle!$I$2:$I$1370,Detalle!$A$2:$A$1370,"2f639739-object_1",Detalle!$B$2:$B$1370,$A55,Detalle!$C$2:$C$1370,$B55) -> 21.730663 | E55: =SUMIFS(Detalle!$I$2:$I$1370,Detalle!$A$2:$A$1370,"5dc9e0d5-object_0",Detalle!$B$2:$B$1370,$A55,Detalle!$C$2:$C$1370,$B55) -> 21.431937 | F55: =SUMIFS(Detalle!$I$2:$I$1370,Detalle!$A$2:$A$1370,"a501b501-object_3",Detalle!$B$2:$B$1370,$A55,Detalle!$C$2:$C$1370,$B55) -> 17.579574 | G55: =SUMIFS(Detalle!$I$2:$I$1370,Detalle!$A$2:$A$1370,"2b65e967-object_0-1",Detalle!$B$2:$B$1370,$A55,Detalle!$C$2:$C$1370,$B55) -> 20.751285 | H55: =SUMIFS(Detalle!$I$2:$I$1370,Detalle!$A$2:$A$1370,"5ed925a3-object_2",Detalle!$B$2:$B$1370,$A55,Detalle!$C$2:$C$1370,$B55) -> 22.453734 | I55: =SUMIFS(Detalle!$I$2:$I$1370,Detalle!$A$2:$A$1370,"70ef0058-object_0",Detalle!$B$2:$B$1370,$A55,Detalle!$C$2:$C$1370,$B55) -> 16.051196 | J55: =SUMIFS(Detalle!$I$2:$I$1370,Detalle!$A$2:$A$1370,"80c13944-object_3",Detalle!$B$2:$B$1370,$A55,Detalle!$C$2:$C$1370,$B55) -> 18.589337 | K55: =SUMIFS(Detalle!$I$2:$I$1370,Detalle!$A$2:$A$1370,"fba550bc-object_1",Detalle!$B$2:$B$1370,$A55,Detalle!$C$2:$C$1370,$B55) -> 17.192875
A56: piernas | B56: largo de pierna (suelo→entrepierna) | C56: =SUMIFS(Detalle!$I$2:$I$1370,Detalle!$A$2:$A$1370,"2a3facb9-object_2",Detalle!$B$2:$B$1370,$A56,Detalle!$C$2:$C$1370,$B56) -> 22.082579 | D56: =SUMIFS(Detalle!$I$2:$I$1370,Detalle!$A$2:$A$1370,"2f639739-object_1",Detalle!$B$2:$B$1370,$A56,Detalle!$C$2:$C$1370,$B56) -> 21.730663 | E56: =SUMIFS(Detalle!$I$2:$I$1370,Detalle!$A$2:$A$1370,"5dc9e0d5-object_0",Detalle!$B$2:$B$1370,$A56,Detalle!$C$2:$C$1370,$B56) -> 21.431937 | F56: =SUMIFS(Detalle!$I$2:$I$1370,Detalle!$A$2:$A$1370,"a501b501-object_3",Detalle!$B$2:$B$1370,$A56,Detalle!$C$2:$C$1370,$B56) -> 17.579574 | G56: =SUMIFS(Detalle!$I$2:$I$1370,Detalle!$A$2:$A$1370,"2b65e967-object_0-1",Detalle!$B$2:$B$1370,$A56,Detalle!$C$2:$C$1370,$B56) -> 20.751285 | H56: =SUMIFS(Detalle!$I$2:$I$1370,Detalle!$A$2:$A$1370,"5ed925a3-object_2",Detalle!$B$2:$B$1370,$A56,Detalle!$C$2:$C$1370,$B56) -> 22.453734 | I56: =SUMIFS(Detalle!$I$2:$I$1370,Detalle!$A$2:$A$1370,"70ef0058-object_0",Detalle!$B$2:$B$1370,$A56,Detalle!$C$2:$C$1370,$B56) -> 16.051196 | J56: =SUMIFS(Detalle!$I$2:$I$1370,Detalle!$A$2:$A$1370,"80c13944-object_3",Detalle!$B$2:$B$1370,$A56,Detalle!$C$2:$C$1370,$B56) -> 18.589337 | K56: =SUMIFS(Detalle!$I$2:$I$1370,Detalle!$A$2:$A$1370,"fba550bc-object_1",Detalle!$B$2:$B$1370,$A56,Detalle!$C$2:$C$1370,$B56) -> 17.192875
A57: piernas | B57: entrepierna → base de cabeza (tronco) | C57: =SUMIFS(Detalle!$I$2:$I$1370,Detalle!$A$2:$A$1370,"2a3facb9-object_2",Detalle!$B$2:$B$1370,$A57,Detalle!$C$2:$C$1370,$B57) -> 31.117897 | D57: =SUMIFS(Detalle!$I$2:$I$1370,Detalle!$A$2:$A$1370,"2f639739-object_1",Detalle!$B$2:$B$1370,$A57,Detalle!$C$2:$C$1370,$B57) -> 28.619689 | E57: =SUMIFS(Detalle!$I$2:$I$1370,Detalle!$A$2:$A$1370,"5dc9e0d5-object_0",Detalle!$B$2:$B$1370,$A57,Detalle!$C$2:$C$1370,$B57) -> 29.867901 | F57: =SUMIFS(Detalle!$I$2:$I$1370,Detalle!$A$2:$A$1370,"a501b501-object_3",Detalle!$B$2:$B$1370,$A57,Detalle!$C$2:$C$1370,$B57) -> 20.420046 | G57: =SUMIFS(Detalle!$I$2:$I$1370,Detalle!$A$2:$A$1370,"2b65e967-object_0-1",Detalle!$B$2:$B$1370,$A57,Detalle!$C$2:$C$1370,$B57) -> 32.449057 | H57: =SUMIFS(Detalle!$I$2:$I$1370,Detalle!$A$2:$A$1370,"5ed925a3-object_2",Detalle!$B$2:$B$1370,$A57,Detalle!$C$2:$C$1370,$B57) -> 29.795601 | I57: =SUMIFS(Detalle!$I$2:$I$1370,Detalle!$A$2:$A$1370,"70ef0058-object_0",Detalle!$B$2:$B$1370,$A57,Detalle!$C$2:$C$1370,$B57) -> 32.399003 | J57: =SUMIFS(Detalle!$I$2:$I$1370,Detalle!$A$2:$A$1370,"80c13944-object_3",Detalle!$B$2:$B$1370,$A57,Detalle!$C$2:$C$1370,$B57) -> 34.610129 | K57: =SUMIFS(Detalle!$I$2:$I$1370,Detalle!$A$2:$A$1370,"fba550bc-object_1",Detalle!$B$2:$B$1370,$A57,Detalle!$C$2:$C$1370,$B57) -> 36.007505
A58: proporción | B58: pierna / altura (%) | C58: =SUMIFS(Detalle!$I$2:$I$1370,Detalle!$A$2:$A$1370,"2a3facb9-object_2",Detalle!$B$2:$B$1370,$A58,Detalle!$C$2:$C$1370,$B58) -> 23.24465 | D58: =SUMIFS(Detalle!$I$2:$I$1370,Detalle!$A$2:$A$1370,"2f639739-object_1",Detalle!$B$2:$B$1370,$A58,Detalle!$C$2:$C$1370,$B58) -> 22.87418 | E58: =SUMIFS(Detalle!$I$2:$I$1370,Detalle!$A$2:$A$1370,"5dc9e0d5-object_0",Detalle!$B$2:$B$1370,$A58,Detalle!$C$2:$C$1370,$B58) -> 22.56003 | F58: =SUMIFS(Detalle!$I$2:$I$1370,Detalle!$A$2:$A$1370,"a501b501-object_3",Detalle!$B$2:$B$1370,$A58,Detalle!$C$2:$C$1370,$B58) -> 18.50492 | G58: =SUMIFS(Detalle!$I$2:$I$1370,Detalle!$A$2:$A$1370,"2b65e967-object_0-1",Detalle!$B$2:$B$1370,$A58,Detalle!$C$2:$C$1370,$B58) -> 21.84348 | H58: =SUMIFS(Detalle!$I$2:$I$1370,Detalle!$A$2:$A$1370,"5ed925a3-object_2",Detalle!$B$2:$B$1370,$A58,Detalle!$C$2:$C$1370,$B58) -> 23.63584 | I58: =SUMIFS(Detalle!$I$2:$I$1370,Detalle!$A$2:$A$1370,"70ef0058-object_0",Detalle!$B$2:$B$1370,$A58,Detalle!$C$2:$C$1370,$B58) -> 16.89586 | J58: =SUMIFS(Detalle!$I$2:$I$1370,Detalle!$A$2:$A$1370,"80c13944-object_3",Detalle!$B$2:$B$1370,$A58,Detalle!$C$2:$C$1370,$B58) -> 19.56822 | K58: =SUMIFS(Detalle!$I$2:$I$1370,Detalle!$A$2:$A$1370,"fba550bc-object_1",Detalle!$B$2:$B$1370,$A58,Detalle!$C$2:$C$1370,$B58) -> 18.0975
A59: proporción | B59: tronco (entrepierna→cuello) / altura (%) | C59: =SUMIFS(Detalle!$I$2:$I$1370,Detalle!$A$2:$A$1370,"2a3facb9-object_2",Detalle!$B$2:$B$1370,$A59,Detalle!$C$2:$C$1370,$B59) -> 32.75535 | D59: =SUMIFS(Detalle!$I$2:$I$1370,Detalle!$A$2:$A$1370,"2f639739-object_1",Detalle!$B$2:$B$1370,$A59,Detalle!$C$2:$C$1370,$B59) -> 30.12582 | E59: =SUMIFS(Detalle!$I$2:$I$1370,Detalle!$A$2:$A$1370,"5dc9e0d5-object_0",Detalle!$B$2:$B$1370,$A59,Detalle!$C$2:$C$1370,$B59) -> 31.43997 | F59: =SUMIFS(Detalle!$I$2:$I$1370,Detalle!$A$2:$A$1370,"a501b501-object_3",Detalle!$B$2:$B$1370,$A59,Detalle!$C$2:$C$1370,$B59) -> 21.49508 | G59: =SUMIFS(Detalle!$I$2:$I$1370,Detalle!$A$2:$A$1370,"2b65e967-object_0-1",Detalle!$B$2:$B$1370,$A59,Detalle!$C$2:$C$1370,$B59) -> 34.15652 | H59: =SUMIFS(Detalle!$I$2:$I$1370,Detalle!$A$2:$A$1370,"5ed925a3-object_2",Detalle!$B$2:$B$1370,$A59,Detalle!$C$2:$C$1370,$B59) -> 31.36416 | I59: =SUMIFS(Detalle!$I$2:$I$1370,Detalle!$A$2:$A$1370,"70ef0058-object_0",Detalle!$B$2:$B$1370,$A59,Detalle!$C$2:$C$1370,$B59) -> 34.10414 | J59: =SUMIFS(Detalle!$I$2:$I$1370,Detalle!$A$2:$A$1370,"80c13944-object_3",Detalle!$B$2:$B$1370,$A59,Detalle!$C$2:$C$1370,$B59) -> 36.43178 | K59: =SUMIFS(Detalle!$I$2:$I$1370,Detalle!$A$2:$A$1370,"fba550bc-object_1",Detalle!$B$2:$B$1370,$A59,Detalle!$C$2:$C$1370,$B59) -> 37.9025
A60: piernas | B60: muslo (25% sobre bastilla→entrepierna, alto) izq: ancho | C60: =SUMIFS(Detalle!$I$2:$I$1370,Detalle!$A$2:$A$1370,"2a3facb9-object_2",Detalle!$B$2:$B$1370,$A60,Detalle!$C$2:$C$1370,$B60) -> 14.194808 | D60: =SUMIFS(Detalle!$I$2:$I$1370,Detalle!$A$2:$A$1370,"2f639739-object_1",Detalle!$B$2:$B$1370,$A60,Detalle!$C$2:$C$1370,$B60) -> 9.7446152 | E60: =SUMIFS(Detalle!$I$2:$I$1370,Detalle!$A$2:$A$1370,"5dc9e0d5-object_0",Detalle!$B$2:$B$1370,$A60,Detalle!$C$2:$C$1370,$B60) -> 13.085285 | F60: =SUMIFS(Detalle!$I$2:$I$1370,Detalle!$A$2:$A$1370,"a501b501-object_3",Detalle!$B$2:$B$1370,$A60,Detalle!$C$2:$C$1370,$B60) -> 9.904601 | G60: =SUMIFS(Detalle!$I$2:$I$1370,Detalle!$A$2:$A$1370,"2b65e967-object_0-1",Detalle!$B$2:$B$1370,$A60,Detalle!$C$2:$C$1370,$B60) -> 13.135593 | H60: =SUMIFS(Detalle!$I$2:$I$1370,Detalle!$A$2:$A$1370,"5ed925a3-object_2",Detalle!$B$2:$B$1370,$A60,Detalle!$C$2:$C$1370,$B60) -> 12.826908 | I60: =SUMIFS(Detalle!$I$2:$I$1370,Detalle!$A$2:$A$1370,"70ef0058-object_0",Detalle!$B$2:$B$1370,$A60,Detalle!$C$2:$C$1370,$B60) -> 14.810566 | J60: =SUMIFS(Detalle!$I$2:$I$1370,Detalle!$A$2:$A$1370,"80c13944-object_3",Detalle!$B$2:$B$1370,$A60,Detalle!$C$2:$C$1370,$B60) -> 12.942727 | K60: =SUMIFS(Detalle!$I$2:$I$1370,Detalle!$A$2:$A$1370,"fba550bc-object_1",Detalle!$B$2:$B$1370,$A60,Detalle!$C$2:$C$1370,$B60) -> 8.6087957
...

Sheet Notas
A1: Medidas SAM 3D · Theo (joven_rubio)
A3: Altura de referencia (mm) | B3: 95 | C3: ← cámbiala (88 / 90 / 95 / 100) y todas las columnas en mm se reescalan
A5: • Fuente: refs/sam3d/theo/*.glb en la rama sam3d-proporciones-theo del repo (commit 4205858). Son 11 GLB del demo de SAM 3D de Meta.
A6: • Los GLB vienen normalizados a una caja unitaria, así que "valor_u" está en esa unidad. Cada modelo se escala por separado a la altura de referencia, sin cruzar datos entre modelos.
A7: • Eje Y = arriba, +Z = frente (la cara mira a +Z). El suelo (Y=0) es el punto más bajo de cada malla.
A8: • Las partes se separan por el color de la textura: cálido = pelo o piel, blanco = camisa, oscuro = chaleco, zapatos u ojos, azul = pantalón o corbata.
A9: • "Base de cabeza" = primera franja central (de arriba hacia abajo) donde domina la ropa, o sea el cuello de camisa. Todo lo de arriba cuenta como cabeza (incluye pelo y orejas).
A10: • Entrepierna: bajando desde la cintura, primera altura donde el corte horizontal ya no cruza el eje central X=0.
A11: • Contornos = perímetro real del corte de la malla en ese plano. En T-pose, el corte de "pecho" atraviesa los brazos y el contorno los incluye.
A12: • Las medidas de manos y brazos cambian según la pose: en T-pose se mide en X (horizontal) y en pose relajada en Y (vertical).
A13: • Como pediste, no se forzó que las medidas cuadren entre sí. Hay valores raros por pelo que tapa, sombras de la textura o piezas fundidas.
A15: Modelo | B15: Pose | C15: Tipo | D15: Estado / aviso | E15: Altura original (u) | F15: Triángulos
A16: 2a3facb9-object_2 | B16: T-pose | C16: Cuerpo completo | D16: Usado en el candidato AMARILLO | E16: 0.95617 | F16: 7681
A17: 2b65e967-object_0-1 | B17: Relajada (brazos abajo) | C17: Cuerpo completo | D17: Toma extra, sin filtrar | E17: 0.99769 | F17: 9733
A18: 2f639739-object_1 | B18: T-pose | C18: Cuerpo completo | D18: Usado en el candidato AMARILLO | E18: 0.99771 | F18: 8656
A19: 38448021-object_5 | B19: Brazos a 45° | C19: Busto deformado (cabeza gigante, cuerpo corto) | D19: Sin pantalón azul: faltan piernas, pantalón y manos | E19: 1.00017 | F19: 14198
A20: 5dc9e0d5-object_0 | B20: T-pose | C20: Cuerpo completo | D20: Toma extra, sin filtrar | E20: 0.93604 | F20: 8996
A21: 5ed925a3-object_2 | B21: Relajada (brazos abajo) | C21: Cuerpo completo | D21: Usado en el candidato AMARILLO | E21: 1.00074 | F21: 7548
A22: 6e95d62d-object_4 | B22: — | C22: Solo cabeza | D22: Solo medidas de cabeza; la base de cabeza queda en 0 | E22: 0.69821 | F22: 11738
A23: 70ef0058-object_0 | B23: Relajada (manos en bolsillos) | C23: Cuerpo completo | D23: Toma extra, sin filtrar | E23: 0.99929 | F23: 9014
A24: 80c13944-object_3 | B24: Relajada (brazos abajo) | C24: Cuerpo completo | D24: Toma extra, sin filtrar | E24: 0.99751 | F24: 9848
A25: a501b501-object_3 | B25: T-pose | C25: Cuerpo completo | D25: Descartado en el README: pico de pelo muy alto descalibra la altura | E25: 1.00001 | F25: 5472
A26: fba550bc-object_1 | B26: Relajada (brazos abajo) | C26: Cuerpo completo | D26: Usado en el candidato AMARILLO | E26: 0.99935 | F26: 9289

Sheet Detalle
A1: Modelo | B1: Parte | C1: Medida | D1: Valor (u) | E1: Altura modelo (u) | F1: Fracción de altura | G1: mm a escala | H1: Sin unidad | I1: Mostrar
A2: 2a3facb9-object_2 | B2: general | C2: altura total | D2: 0.95617 | E2: 0.95617 | F2: =IF(H2=1,"",D2/E2) -> 1 | G2: =IF(H2=1,"",D2/E2*Notas!$B$3) -> 95 | H2: 0 | I2: =IF(H2=1,D2,G2) -> 95
A3: 2a3facb9-object_2 | B3: general | C3: ancho total (X) | D3: 0.9953 | E3: 0.95617 | F3: =IF(H3=1,"",D3/E3) -> 1.0409237 | G3: =IF(H3=1,"",D3/E3*Notas!$B$3) -> 98.88775 | H3: 0 | I3: =IF(H3=1,D3,G3) -> 98.88775
A4: 2a3facb9-object_2 | B4: general | C4: fondo total (Z) | D4: 0.36919 | E4: 0.95617 | F4: =IF(H4=1,"",D4/E4) -> 0.38611335 | G4: =IF(H4=1,"",D4/E4*Notas!$B$3) -> 36.680768 | H4: 0 | I4: =IF(H4=1,D4,G4) -> 36.680768
A5: 2a3facb9-object_2 | B5: general | C5: triángulos | D5: 7681 | E5: 0.95617 | F5: =IF(H5=1,"",D5/E5) | G5: =IF(H5=1,"",D5/E5*Notas!$B$3) | H5: 1 | I5: =IF(H5=1,D5,G5) -> 7681
A6: 2a3facb9-object_2 | B6: general | C6: vértices (soldados) | D6: 3841 | E6: 0.95617 | F6: =IF(H6=1,"",D6/E6) | G6: =IF(H6=1,"",D6/E6*Notas!$B$3) | H6: 1 | I6: =IF(H6=1,D6,G6) -> 3841
A7: 2a3facb9-object_2 | B7: general | C7: área de superficie (u²) | D7: 1.52798 | E7: 0.95617 | F7: =IF(H7=1,"",D7/E7) | G7: =IF(H7=1,"",D7/E7*Notas!$B$3) | H7: 1 | I7: =IF(H7=1,D7,G7) -> 1.52798
A8: 2a3facb9-object_2 | B8: general | C8: volumen aprox (u³) | D8: 0.05452 | E8: 0.95617 | F8: =IF(H8=1,"",D8/E8) | G8: =IF(H8=1,"",D8/E8*Notas!$B$3) | H8: 1 | I8: =IF(H8=1,D8,G8) -> 0.05452
A9: 2a3facb9-object_2 | B9: color | C9: % superficie calido | D9: 50.94077 | E9: 0.95617 | F9: =IF(H9=1,"",D9/E9) | G9: =IF(H9=1,"",D9/E9*Notas!$B$3) | H9: 1 | I9: =IF(H9=1,D9,G9) -> 50.94077
A10: 2a3facb9-object_2 | B10: color | C10: % superficie blanco | D10: 10.21058 | E10: 0.95617 | F10: =IF(H10=1,"",D10/E10) | G10: =IF(H10=1,"",D10/E10*Notas!$B$3) | H10: 1 | I10: =IF(H10=1,D10,G10) -> 10.21058
A11: 2a3facb9-object_2 | B11: color | C11: % superficie oscuro | D11: 29.81625 | E11: 0.95617 | F11: =IF(H11=1,"",D11/E11) | G11: =IF(H11=1,"",D11/E11*Notas!$B$3) | H11: 1 | I11: =IF(H11=1,D11,G11) -> 29.81625
A12: 2a3facb9-object_2 | B12: color | C12: % superficie azul | D12: 9.0324 | E12: 0.95617 | F12: =IF(H12=1,"",D12/E12) | G12: =IF(H12=1,"",D12/E12*Notas!$B$3) | H12: 1 | I12: =IF(H12=1,D12,G12) -> 9.0324
A13: 2a3facb9-object_2 | B13: cabeza | C13: altura del cuello de camisa / base de cabeza | D13: 0.53546 | E13: 0.95617 | F13: =IF(H13=1,"",D13/E13) -> 0.56000502 | G13: =IF(H13=1,"",D13/E13*Notas!$B$3) -> 53.200477 | H13: 0 | I13: =IF(H13=1,D13,G13) -> 53.200477
